<sdf version='1.5'>
  <model name='OrcaXL'>
    <pose>0 0 0 0 0 0</pose>
    <link name='base_link'>
      <pose>0 0 0 0 0 0</pose>
      <inertial>
        <pose>0.2 0 0.5 0 0 0</pose>
        <mass>72</mass>
        <inertia>
          <ixx>10.3</ixx>
          <ixy>0</ixy>
          <ixz>0</ixz>
          <iyy>10.3</iyy>
          <iyz>0</iyz>
          <izz>10.6</izz>
        </inertia>
      </inertial>
      <collision name='base_link_collision'>
        <pose>0 0 0 0 0 0</pose>
        <geometry>
          <box>
            <size>1.4 3 0.3</size>
          </box>
        </geometry>
        <surface>
          <contact>
            <ode>
              <kp>100000</kp>
              <kd>1.0</kd>
              <max_vel>0.1</max_vel>
              <min_depth>0.001</min_depth>
            </ode>
          </contact>
          <friction>
            <ode/>
          </friction>
        </surface>
      </collision>
      <visual name='base_link_visual'>
        <pose>1.1 0 0.30 1.5707963268 0 1.5707963268</pose>
        <geometry>
          <mesh>
            <scale>1 1 1</scale>
            <uri>model://OrcaXL/meshes/fuse_mesh.dae</uri>
          </mesh>
        </geometry>
        <material>
          <script>
            <name>Gazebo/DarkGrey</name>
            <uri>__default__</uri>
          </script>
        </material>
      </visual>
      <gravity>1</gravity>
      <velocity_decay/>
      <self_collide>0</self_collide>
    </link>
    <link name='OrcaXL/imu_link'>
      <pose>0.2 0 0.5 0 0 0</pose>
      <inertial>
        <pose>0 0 0 0 0 0</pose>
        <mass>0.015</mass>
        <inertia>
          <ixx>1e-05</ixx>
          <ixy>0</ixy>
          <ixz>0</ixz>
          <iyy>1e-05</iyy>
          <iyz>0</iyz>
          <izz>1e-05</izz>
        </inertia>
      </inertial>

    </link>
    <joint name='OrcaXL/imu_joint' type='revolute'>
      <child>OrcaXL/imu_link</child>
      <parent>base_link</parent>
      <axis>
        <xyz>1 0 0</xyz>
        <limit>
          <lower>0</lower>
          <upper>0</upper>
          <effort>0</effort>
          <velocity>0</velocity>
        </limit>
        <dynamics>
          <spring_reference>0</spring_reference>
          <spring_stiffness>0</spring_stiffness>
        </dynamics>
        <use_parent_model_frame>1</use_parent_model_frame>
      </axis>
    </joint>

    <include>
      <uri>model://airspeed</uri>
      <pose>0.2 0 0.5 0 0 0</pose>
      <name>airspeed</name>
    </include>
    <joint name='airspeed_joint' type='fixed'>
      <child>airspeed::link</child>
      <parent>base_link</parent>
    </joint>


    <link name='front_tilt'>
      <pose>1.05 0 0.3 0 -1.5707963268 0</pose>
      <inertial>
        <pose>0 0 0 0 0 0</pose>
        <mass>0.05</mass>
        <inertia>
          <ixx>0.0166704</ixx>
          <ixy>0</ixy>
          <ixz>0</ixz>
          <iyy>0.0166704</iyy>
          <iyz>0</iyz>
          <izz>0.0167604</izz>
        </inertia>
      </inertial>
      <velocity_decay/>
      <self_collide>0</self_collide>
      <visual name='front_tilt_visual'>
        <pose>0 0 0 1.5707963268 0 0</pose>
        <geometry>
          <cylinder>
            <length>2.4</length>
            <radius>0.02</radius>
          </cylinder>
        </geometry>
        <material>
          <script>
            <name>Gazebo/DarkGrey</name>
            <uri>__default__</uri>
          </script>
        </material>
      </visual>

    </link>
    <joint name='front_tilt_joint' type='revolute'>
      <child>front_tilt</child>
      <parent>base_link</parent>
      <axis>
        <xyz>0 1 0</xyz>
        <limit>
          <lower>-1.5</lower>
          <upper>1.5</upper>
        </limit>
        <dynamics>
          <friction>1.0</friction>
          <spring_reference>0</spring_reference>
          <spring_stiffness>0</spring_stiffness>
        </dynamics>
        <use_parent_model_frame>1</use_parent_model_frame>
      </axis>
    </joint>

    <link name='front_right_wing'>
      <pose>1.05 -0.4 0.35 0 0 0</pose>
      <inertial>
        <pose>0 0 0 0 0 0</pose>
        <mass>0.05</mass>
        <inertia>
          <ixx>0.0166704</ixx>
          <ixy>0</ixy>
          <ixz>0</ixz>
          <iyy>0.0166704</iyy>
          <iyz>0</iyz>
          <izz>0.0167604</izz>
        </inertia>
      </inertial>
      <visual name='front_right_wing_visual'>
        <pose>0 0.4 0 0 0 1.5707963268</pose>
        <geometry>
          <mesh>
            <scale>1 1 1</scale>
            <uri>model://OrcaXL/meshes/front_wing.dae</uri>
          </mesh>
        </geometry>
        <material>
          <script>
            <name>Gazebo/DarkGrey</name>
            <uri>__default__</uri>
          </script>
        </material>
      </visual>
      <gravity>1</gravity>
      <velocity_decay/>
      <self_collide>0</self_collide>
    </link>
    <joint name='front_right_wing_joint' type='fixed'>
      <child>front_right_wing</child>
      <parent>front_tilt</parent>
    </joint>

    <link name='front_left_wing'>
      <pose>1.05 0.4 0.35 0 0 0</pose>
      <inertial>
        <pose>0 0 0 0 0 0</pose>
        <mass>0.05</mass>
        <inertia>
          <ixx>0.0166704</ixx>
          <ixy>0</ixy>
          <ixz>0</ixz>
          <iyy>0.0166704</iyy>
          <iyz>0</iyz>
          <izz>0.0167604</izz>
        </inertia>
      </inertial>
      <visual name='front_left_wing_visual'>
        <pose>0 1.25 0 0 0 1.5707963268</pose>
        <geometry>
          <mesh>
            <scale>1 1 1</scale>
            <uri>model://OrcaXL/meshes/front_wing.dae</uri>
          </mesh>
        </geometry>
        <material>
          <script>
            <name>Gazebo/DarkGrey</name>
            <uri>__default__</uri>
          </script>
        </material>
      </visual>
      <gravity>1</gravity>
      <velocity_decay/>
      <self_collide>0</self_collide>
    </link>
    <joint name='front_left_wing_joint' type='fixed'>
      <child>front_left_wing</child>
      <parent>front_tilt</parent>
    </joint>

    <link name='motor_0'>
      <pose>1.05 1.2 0.35 0 0 0</pose>
      <inertial>
        <pose>0 0 0 0 0 0</pose>
        <mass>0.05</mass>
        <inertia>
          <ixx>0.0166704</ixx>
          <ixy>0</ixy>
          <ixz>0</ixz>
          <iyy>0.0166704</iyy>
          <iyz>0</iyz>
          <izz>0.0167604</izz>
        </inertia>
      </inertial>
      <collision name='motor_0_collision'>
        <pose>0 0 0 0 0 0</pose>
        <geometry>
          <cylinder>
            <length>0.035</length>
            <radius>0.02</radius>
          </cylinder>
        </geometry>
        <surface>
          <contact>
            <ode/>
          </contact>
          <friction>
            <ode/>
          </friction>
        </surface>
      </collision>
      <visual name='motor_0_visual'>
        <pose>0 0 0 0 0 0</pose>
        <geometry>
          <cylinder>
            <length>0.035</length>
            <radius>0.02</radius>
          </cylinder>
        </geometry>
        <material>
          <script>
            <name>Gazebo/DarkGrey</name>
            <uri>__default__</uri>
          </script>
        </material>
      </visual>
      <gravity>1</gravity>
      <velocity_decay/>
      <self_collide>0</self_collide>
    </link>
    <joint name='motor_0_joint' type='fixed'>
      <child>motor_0</child>
      <parent>front_tilt</parent>
    </joint>

    <link name='rotor_0'>
      <pose>1.05 1.2 0.4 0 0 0</pose>
      <inertial>
        <pose>0 0 0 0 0 0</pose>
        <mass>0.005</mass>
        <inertia>
          <ixx>9.75e-07</ixx>
          <ixy>0</ixy>
          <ixz>0</ixz>
          <iyy>0.000166704</iyy>
          <iyz>0</iyz>
          <izz>0.000167604</izz>
        </inertia>
      </inertial>
      <collision name='rotor_0_collision'>
        <pose>0 0 0 0 0 0</pose>
        <geometry>
          <cylinder>
            <length>0.005</length>
            <radius>0.1</radius>
          </cylinder>
        </geometry>
        <surface>
          <contact>
            <ode/>
          </contact>
          <friction>
            <ode/>
          </friction>
        </surface>
      </collision>
      <visual name='rotor_0_visual'>
        <pose>0 0 0 0 0 0</pose>
        <geometry>
          <mesh>
            <scale>1.4 1.4 1</scale>
            <uri>model://OrcaXL/meshes/iris_prop_cw.dae</uri>
          </mesh>
        </geometry>
        <material>
          <script>
            <name>Gazebo/Blue</name>
            <uri>__default__</uri>
          </script>
        </material>
      </visual>
      <gravity>1</gravity>
      <velocity_decay/>
      <self_collide>0</self_collide>
    </link>
    <joint name='rotor_0_joint' type='revolute'>
      <child>rotor_0</child>
      <parent>motor_0</parent>
      <axis>
        <xyz>0 0 1</xyz>
        <limit>
          <lower>-1e+16</lower>
          <upper>1e+16</upper>
        </limit>
        <dynamics>
          <spring_reference>0</spring_reference>
          <spring_stiffness>0</spring_stiffness>
        </dynamics>
        <use_parent_model_frame>1</use_parent_model_frame>
      </axis>
    </joint>


    <link name='motor_1'>
      <pose>1.05 0.6 0.35 0 0 0</pose>
      <inertial>
        <pose>0 0 0 0 0 0</pose>
        <mass>0.05</mass>
        <inertia>
          <ixx>0.0166704</ixx>
          <ixy>0</ixy>
          <ixz>0</ixz>
          <iyy>0.0166704</iyy>
          <iyz>0</iyz>
          <izz>0.0167604</izz>
        </inertia>
      </inertial>
      <collision name='motor_1_collision'>
        <pose>0 0 0 0 0 0</pose>
        <geometry>
          <cylinder>
            <length>0.035</length>
            <radius>0.02</radius>
          </cylinder>
        </geometry>
        <surface>
          <contact>
            <ode/>
          </contact>
          <friction>
            <ode/>
          </friction>
        </surface>
      </collision>
      <visual name='motor_1_visual'>
        <pose>0 0 0 0 0 0</pose>
        <geometry>
          <cylinder>
            <length>0.035</length>
            <radius>0.02</radius>
          </cylinder>
        </geometry>
        <material>
          <script>
            <name>Gazebo/DarkGrey</name>
            <uri>__default__</uri>
          </script>
        </material>
      </visual>
      <gravity>1</gravity>
      <velocity_decay/>
      <self_collide>0</self_collide>
    </link>
    <joint name='motor_1_joint' type='fixed'>
      <child>motor_1</child>
      <parent>front_tilt</parent>
    </joint>

    <link name='rotor_1'>
      <pose>1.05 0.6 0.4 0 0 0</pose>
      <inertial>
        <pose>0 0 0 0 0 0</pose>
        <mass>0.005</mass>
        <inertia>
          <ixx>9.75e-07</ixx>
          <ixy>0</ixy>
          <ixz>0</ixz>
          <iyy>0.000166704</iyy>
          <iyz>0</iyz>
          <izz>0.000167604</izz>
        </inertia>
      </inertial>
      <collision name='rotor_1_collision'>
        <pose>0 0 0 0 0 0</pose>
        <geometry>
          <cylinder>
            <length>0.005</length>
            <radius>0.1</radius>
          </cylinder>
        </geometry>
        <surface>
          <contact>
            <ode/>
          </contact>
          <friction>
            <ode/>
          </friction>
        </surface>
      </collision>
      <visual name='rotor_1_visual'>
        <pose>0 0 0 0 0 0</pose>
        <geometry>
          <mesh>
            <scale>1.4 1.4 1</scale>
            <uri>model://OrcaXL/meshes/iris_prop_ccw.dae</uri>
          </mesh>
        </geometry>
        <material>
          <script>
            <name>Gazebo/DarkGrey</name>
            <uri>__default__</uri>
          </script>
        </material>
      </visual>
      <gravity>1</gravity>
      <velocity_decay/>
      <self_collide>0</self_collide>
    </link>
    <joint name='rotor_1_joint' type='revolute'>
      <child>rotor_1</child>
      <parent>motor_1</parent>
      <axis>
        <xyz>0 0 1</xyz>
        <limit>
          <lower>-1e+16</lower>
          <upper>1e+16</upper>
        </limit>
        <dynamics>
          <spring_reference>0</spring_reference>
          <spring_stiffness>0</spring_stiffness>
        </dynamics>
        <use_parent_model_frame>1</use_parent_model_frame>
      </axis>
    </joint>


    <link name='motor_2'>
      <pose>1.05 -0.6 0.35 0 0 0</pose>
      <inertial>
        <pose>0 0 0 0 0 0</pose>
        <mass>0.05</mass>
        <inertia>
          <ixx>0.0166704</ixx>
          <ixy>0</ixy>
          <ixz>0</ixz>
          <iyy>0.0166704</iyy>
          <iyz>0</iyz>
          <izz>0.0167604</izz>
        </inertia>
      </inertial>
      <collision name='motor_2_collision'>
        <pose>0 0 0 0 0 0</pose>
        <geometry>
          <cylinder>
            <length>0.035</length>
            <radius>0.02</radius>
          </cylinder>
        </geometry>
        <surface>
          <contact>
            <ode/>
          </contact>
          <friction>
            <ode/>
          </friction>
        </surface>
      </collision>
      <visual name='motor_2_visual'>
        <pose>0 0 0 0 0 0</pose>
        <geometry>
          <cylinder>
            <length>0.035</length>
            <radius>0.02</radius>
          </cylinder>
        </geometry>
        <material>
          <script>
            <name>Gazebo/DarkGrey</name>
            <uri>__default__</uri>
          </script>
        </material>
      </visual>
      <gravity>1</gravity>
      <velocity_decay/>
      <self_collide>0</self_collide>
    </link>
    <joint name='motor_2_joint' type='fixed'>
      <child>motor_2</child>
      <parent>front_tilt</parent>
    </joint>

    <link name='rotor_2'>
      <pose>1.05 -0.6 0.4 0 0 0</pose>
      <inertial>
        <pose>0 0 0 0 0 0</pose>
        <mass>0.005</mass>
        <inertia>
          <ixx>9.75e-07</ixx>
          <ixy>0</ixy>
          <ixz>0</ixz>
          <iyy>0.000166704</iyy>
          <iyz>0</iyz>
          <izz>0.000167604</izz>
        </inertia>
      </inertial>
      <collision name='rotor_2_collision'>
        <pose>0 0 0 0 0 0</pose>
        <geometry>
          <cylinder>
            <length>0.005</length>
            <radius>0.1</radius>
          </cylinder>
        </geometry>
        <surface>
          <contact>
            <ode/>
          </contact>
          <friction>
            <ode/>
          </friction>
        </surface>
      </collision>
      <visual name='rotor_2_visual'>
        <pose>0 0 0 0 0 0</pose>
        <geometry>
          <mesh>
            <scale>1.4 1.4 1</scale>
            <uri>model://OrcaXL/meshes/iris_prop_cw.dae</uri>
          </mesh>
        </geometry>
        <material>
          <script>
            <name>Gazebo/DarkGrey</name>
            <uri>__default__</uri>
          </script>
        </material>
      </visual>
      <gravity>1</gravity>
      <velocity_decay/>
      <self_collide>0</self_collide>
    </link>
    <joint name='rotor_2_joint' type='revolute'>
      <child>rotor_2</child>
      <parent>motor_2</parent>
      <axis>
        <xyz>0 0 1</xyz>
        <limit>
          <lower>-1e+16</lower>
          <upper>1e+16</upper>
        </limit>
        <dynamics>
          <spring_reference>0</spring_reference>
          <spring_stiffness>0</spring_stiffness>
        </dynamics>
        <use_parent_model_frame>1</use_parent_model_frame>
      </axis>
    </joint>

    <link name='motor_3'>
      <pose>1.05 -1.2 0.35 0 0 0</pose>
      <inertial>
        <pose>0 0 0 0 0 0</pose>
        <mass>0.05</mass>
        <inertia>
          <ixx>0.0166704</ixx>
          <ixy>0</ixy>
          <ixz>0</ixz>
          <iyy>0.0166704</iyy>
          <iyz>0</iyz>
          <izz>0.0167604</izz>
        </inertia>
      </inertial>
      <collision name='motor_3_collision'>
        <pose>0 0 0 0 0 0</pose>
        <geometry>
          <cylinder>
            <length>0.035</length>
            <radius>0.02</radius>
          </cylinder>
        </geometry>
        <surface>
          <contact>
            <ode/>
          </contact>
          <friction>
            <ode/>
          </friction>
        </surface>
      </collision>
      <visual name='motor_3_visual'>
        <pose>0 0 0 0 0 0</pose>
        <geometry>
          <cylinder>
            <length>0.035</length>
            <radius>0.02</radius>
          </cylinder>
        </geometry>
        <material>
          <script>
            <name>Gazebo/DarkGrey</name>
            <uri>__default__</uri>
          </script>
        </material>
      </visual>
      <gravity>1</gravity>
      <velocity_decay/>
      <self_collide>0</self_collide>
    </link>
    <joint name='motor_3_joint' type='fixed'>
      <child>motor_3</child>
      <parent>front_tilt</parent>
    </joint>

    <link name='rotor_3'>
      <pose>1.05 -1.2 0.4 0 0 0</pose>
      <inertial>
        <pose>0 0 0 0 0 0</pose>
        <mass>0.005</mass>
        <inertia>
          <ixx>9.75e-07</ixx>
          <ixy>0</ixy>
          <ixz>0</ixz>
          <iyy>0.000166704</iyy>
          <iyz>0</iyz>
          <izz>0.000167604</izz>
        </inertia>
      </inertial>
      <collision name='rotor_3_collision'>
        <pose>0 0 0 0 0 0</pose>
        <geometry>
          <cylinder>
            <length>0.005</length>
            <radius>0.1</radius>
          </cylinder>
        </geometry>
        <surface>
          <contact>
            <ode/>
          </contact>
          <friction>
            <ode/>
          </friction>
        </surface>
      </collision>
      <visual name='rotor_3_visual'>
        <pose>0 0 0 0 0 0</pose>
        <geometry>
          <mesh>
            <scale>1.4 1.4 1</scale>
            <uri>model://OrcaXL/meshes/iris_prop_ccw.dae</uri>
          </mesh>
        </geometry>
        <material>
          <script>
            <name>Gazebo/Blue</name>
            <uri>__default__</uri>
          </script>
        </material>
      </visual>
      <gravity>1</gravity>
      <velocity_decay/>
      <self_collide>0</self_collide>
    </link>
    <joint name='rotor_3_joint' type='revolute'>
      <child>rotor_3</child>
      <parent>motor_3</parent>
      <axis>
        <xyz>0 0 1</xyz>
        <limit>
          <lower>-1e+16</lower>
          <upper>1e+16</upper>
        </limit>
        <dynamics>
          <spring_reference>0</spring_reference>
          <spring_stiffness>0</spring_stiffness>
        </dynamics>
        <use_parent_model_frame>1</use_parent_model_frame>
      </axis>
    </joint>

    <link name='rear_tilt'>
      <pose>-0.7 0 0.8 0 -1.5707963268 0</pose>
      <inertial>
        <pose>0 0 0 0 0 0</pose>
        <mass>0.05</mass>
        <inertia>
          <ixx>0.0166704</ixx>
          <ixy>0</ixy>
          <ixz>0</ixz>
          <iyy>0.0166704</iyy>
          <iyz>0</iyz>
          <izz>0.0167604</izz>
        </inertia>
      </inertial>
      <velocity_decay/>
      <self_collide>0</self_collide>
      <visual name='rear_tilt_visual'>
        <pose>0 0 0 1.5707963268 0 0</pose>
        <geometry>
          <cylinder>
            <length>2.4</length>
            <radius>0.02</radius>
          </cylinder>
        </geometry>
        <material>
          <script>
            <name>Gazebo/DarkGrey</name>
            <uri>__default__</uri>
          </script>
        </material>
      </visual>
    </link>
    <joint name='rear_tilt_joint' type='revolute'>
      <child>rear_tilt</child>
      <parent>base_link</parent>
      <axis>
        <xyz>0 1 0</xyz>
        <limit>
          <lower>-1.5</lower>
          <upper>1.5</upper>
        </limit>
        <dynamics>
          <friction>1.0</friction>
          <spring_reference>0</spring_reference>
          <spring_stiffness>0</spring_stiffness>
        </dynamics>
        <use_parent_model_frame>1</use_parent_model_frame>
      </axis>
    </joint>

      <link name='rear_right_wing'>
      <pose>-0.7 -0.4 0.65 0 0 0</pose>
      <inertial>
        <pose>0 0 0 0 0 0</pose>
        <mass>0.05</mass>
        <inertia>
          <ixx>0.0166704</ixx>
          <ixy>0</ixy>
          <ixz>0</ixz>
          <iyy>0.0166704</iyy>
          <iyz>0</iyz>
          <izz>0.0167604</izz>
        </inertia>
      </inertial>
      <collision name='rear_right_wing_collision'>
        <pose>0 0 0 0 0 0</pose>
        <geometry>
          <cylinder>
            <length>0.035</length>
            <radius>0.02</radius>
          </cylinder>
        </geometry>
        <surface>
          <contact>
            <ode/>
          </contact>
          <friction>
            <ode/>
          </friction>
        </surface>
      </collision>
      <visual name='rear_right_wing_visual'>
        <pose>0.5 0.4 1.9 0 0 1.5707963268</pose>
        <geometry>
          <mesh>
            <scale>1 1 1</scale>
            <uri>model://OrcaXL/meshes/rear_wing.dae</uri>
          </mesh>
        </geometry>
        <material>
          <script>
            <name>Gazebo/DarkGrey</name>
            <uri>__default__</uri>
          </script>
        </material>
      </visual>
      <gravity>1</gravity>
      <velocity_decay/>
      <self_collide>0</self_collide>
    </link>
    <joint name='rear_right_wing_joint' type='fixed'>
      <child>rear_right_wing</child>
      <parent>rear_tilt</parent>
    </joint>

    <link name='rear_left_wing'>
      <pose>-0.7 0.4 0.65 0 0 0</pose>
      <inertial>
        <pose>0 0 0 0 0 0</pose>
        <mass>0.05</mass>
        <inertia>
          <ixx>0.0166704</ixx>
          <ixy>0</ixy>
          <ixz>0</ixz>
          <iyy>0.0166704</iyy>
          <iyz>0</iyz>
          <izz>0.0167604</izz>
        </inertia>
      </inertial>
      <collision name='rear_left_wing_collision'>
        <pose>0 0 0 0 0 0</pose>
        <geometry>
          <cylinder>
            <length>0.035</length>
            <radius>0.02</radius>
          </cylinder>
        </geometry>
        <surface>
          <contact>
            <ode/>
          </contact>
          <friction>
            <ode/>
          </friction>
        </surface>
      </collision>
      <visual name='rear_left_wing_visual'>
        <pose>0.5 1.5 1.9 0 0 1.5707963268</pose>
        <geometry>
          <mesh>
            <scale>1 1 1</scale>
            <uri>model://OrcaXL/meshes/rear_wing.dae</uri>
          </mesh>
        </geometry>
        <material>
          <script>
            <name>Gazebo/DarkGrey</name>
            <uri>__default__</uri>
          </script>
        </material>
      </visual>
      <gravity>1</gravity>
      <velocity_decay/>
      <self_collide>0</self_collide>
    </link>
    <joint name='rear_left_wing_joint' type='fixed'>
      <child>rear_left_wing</child>
      <parent>rear_tilt</parent>
    </joint>

    <link name='motor_4'>
      <pose>-0.7 1.5 0.85 0 0 0</pose>
      <inertial>
        <pose>0 0 0 0 0 0</pose>
        <mass>0.05</mass>
        <inertia>
          <ixx>0.0166704</ixx>
          <ixy>0</ixy>
          <ixz>0</ixz>
          <iyy>0.0166704</iyy>
          <iyz>0</iyz>
          <izz>0.0167604</izz>
        </inertia>
      </inertial>
      <collision name='motor_4_collision'>
        <pose>0 0 0 0 0 0</pose>
        <geometry>
          <cylinder>
            <length>0.035</length>
            <radius>0.02</radius>
          </cylinder>
        </geometry>
        <surface>
          <contact>
            <ode/>
          </contact>
          <friction>
            <ode/>
          </friction>
        </surface>
      </collision>
      <visual name='motor_4_visual'>
        <pose>0 0 0 0 0 0</pose>
        <geometry>
          <cylinder>
            <length>0.035</length>
            <radius>0.02</radius>
          </cylinder>
        </geometry>
        <material>
          <script>
            <name>Gazebo/DarkGrey</name>
            <uri>__default__</uri>
          </script>
        </material>
      </visual>
      <gravity>1</gravity>
      <velocity_decay/>
      <self_collide>0</self_collide>
    </link>
    <joint name='motor_4_joint' type='fixed'>
      <child>motor_4</child>
      <parent>rear_tilt</parent>
    </joint>

    <link name='rotor_4'>
      <pose>-0.7 1.5 0.9 0 0 0</pose>
      <inertial>
        <pose>0 0 0 0 0 0</pose>
        <mass>0.005</mass>
        <inertia>
          <ixx>9.75e-07</ixx>
          <ixy>0</ixy>
          <ixz>0</ixz>
          <iyy>0.000166704</iyy>
          <iyz>0</iyz>
          <izz>0.000167604</izz>
        </inertia>
      </inertial>
      <collision name='rotor_4_collision'>
        <pose>0 0 0 0 0 0</pose>
        <geometry>
          <cylinder>
            <length>0.005</length>
            <radius>0.1</radius>
          </cylinder>
        </geometry>
        <surface>
          <contact>
            <ode/>
          </contact>
          <friction>
            <ode/>
          </friction>
        </surface>
      </collision>
      <visual name='rotor_4_visual'>
        <pose>0 0 0 0 0 0</pose>
        <geometry>
          <mesh>
            <scale>1.4 1.4 1</scale>
            <uri>model://OrcaXL/meshes/iris_prop_cw.dae</uri>
          </mesh>
        </geometry>
        <material>
          <script>
            <name>Gazebo/Blue</name>
            <uri>__default__</uri>
          </script>
        </material>
      </visual>
      <gravity>1</gravity>
      <velocity_decay/>
      <self_collide>0</self_collide>
    </link>
    <joint name='rotor_4_joint' type='revolute'>
      <child>rotor_4</child>
      <parent>motor_4</parent>
      <axis>
        <xyz>0 0 1</xyz>
        <limit>
          <lower>-1e+16</lower>
          <upper>1e+16</upper>
        </limit>
        <dynamics>
          <spring_reference>0</spring_reference>
          <spring_stiffness>0</spring_stiffness>
        </dynamics>
        <use_parent_model_frame>1</use_parent_model_frame>
      </axis>
    </joint>


    <link name='motor_5'>
      <pose>-0.7 0.6 0.85 0 0</pose>
      <inertial>
        <pose>0 0 0 0 0 0</pose>
        <mass>0.05</mass>
        <inertia>
          <ixx>0.0166704</ixx>
          <ixy>0</ixy>
          <ixz>0</ixz>
          <iyy>0.0166704</iyy>
          <iyz>0</iyz>
          <izz>0.0167604</izz>
        </inertia>
      </inertial>
      <collision name='motor_5_collision'>
        <pose>0 0 0 0 0 0</pose>
        <geometry>
          <cylinder>
            <length>0.035</length>
            <radius>0.02</radius>
          </cylinder>
        </geometry>
        <surface>
          <contact>
            <ode/>
          </contact>
          <friction>
            <ode/>
          </friction>
        </surface>
      </collision>
      <visual name='motor_5_visual'>
        <pose>0 0 0 0 0 0</pose>
        <geometry>
          <cylinder>
            <length>0.035</length>
            <radius>0.02</radius>
          </cylinder>
        </geometry>
        <material>
          <script>
            <name>Gazebo/DarkGrey</name>
            <uri>__default__</uri>
          </script>
        </material>
      </visual>
      <gravity>1</gravity>
      <velocity_decay/>
      <self_collide>0</self_collide>
    </link>
    <joint name='motor_5_joint' type='fixed'>
      <child>motor_5</child>
      <parent>rear_tilt</parent>
    </joint>

    <link name='rotor_5'>
      <pose>-0.7 0.6 0.9 0 0 0</pose>
      <inertial>
        <pose>0 0 0 0 0 0</pose>
        <mass>0.005</mass>
        <inertia>
          <ixx>9.75e-07</ixx>
          <ixy>0</ixy>
          <ixz>0</ixz>
          <iyy>0.000166704</iyy>
          <iyz>0</iyz>
          <izz>0.000167604</izz>
        </inertia>
      </inertial>
      <collision name='rotor_5_collision'>
        <pose>0 0 0 0 0 0</pose>
        <geometry>
          <cylinder>
            <length>0.005</length>
            <radius>0.1</radius>
          </cylinder>
        </geometry>
        <surface>
          <contact>
            <ode/>
          </contact>
          <friction>
            <ode/>
          </friction>
        </surface>
      </collision>
      <visual name='rotor_5_visual'>
        <pose>0 0 0 0 0 0</pose>
        <geometry>
          <mesh>
            <scale>1.4 1.4 1</scale>
            <uri>model://OrcaXL/meshes/iris_prop_ccw.dae</uri>
          </mesh>
        </geometry>
        <material>
          <script>
            <name>Gazebo/DarkGrey</name>
            <uri>__default__</uri>
          </script>
        </material>
      </visual>
      <gravity>1</gravity>
      <velocity_decay/>
      <self_collide>0</self_collide>
    </link>
    <joint name='rotor_5_joint' type='revolute'>
      <child>rotor_5</child>
      <parent>motor_5</parent>
      <axis>
        <xyz>0 0 1</xyz>
        <limit>
          <lower>-1e+16</lower>
          <upper>1e+16</upper>
        </limit>
        <dynamics>
          <spring_reference>0</spring_reference>
          <spring_stiffness>0</spring_stiffness>
        </dynamics>
        <use_parent_model_frame>1</use_parent_model_frame>
      </axis>
    </joint>


    <link name='motor_6'>
      <pose>-0.7 -0.6 0.85 0 0</pose>
      <inertial>
        <pose>0 0 0 0 0 0</pose>
        <mass>0.05</mass>
        <inertia>
          <ixx>0.0166704</ixx>
          <ixy>0</ixy>
          <ixz>0</ixz>
          <iyy>0.0166704</iyy>
          <iyz>0</iyz>
          <izz>0.0167604</izz>
        </inertia>
      </inertial>
      <collision name='motor_6_collision'>
        <pose>0 0 0 0 0 0</pose>
        <geometry>
          <cylinder>
            <length>0.035</length>
            <radius>0.02</radius>
          </cylinder>
        </geometry>
        <surface>
          <contact>
            <ode/>
          </contact>
          <friction>
            <ode/>
          </friction>
        </surface>
      </collision>
      <visual name='motor_6_visual'>
        <pose>0 0 0 0 0 0</pose>
        <geometry>
          <cylinder>
            <length>0.035</length>
            <radius>0.02</radius>
          </cylinder>
        </geometry>
        <material>
          <script>
            <name>Gazebo/DarkGrey</name>
            <uri>__default__</uri>
          </script>
        </material>
      </visual>
      <gravity>1</gravity>
      <velocity_decay/>
      <self_collide>0</self_collide>
    </link>
    <joint name='motor_6_joint' type='fixed'>
      <child>motor_6</child>
      <parent>rear_tilt</parent>
    </joint>

    <link name='rotor_6'>
      <pose>-0.7 -0.6 0.9 0 0 0</pose>
      <inertial>
        <pose>0 0 0 0 0 0</pose>
        <mass>0.005</mass>
        <inertia>
          <ixx>9.75e-07</ixx>
          <ixy>0</ixy>
          <ixz>0</ixz>
          <iyy>0.000166704</iyy>
          <iyz>0</iyz>
          <izz>0.000167604</izz>
        </inertia>
      </inertial>
      <collision name='rotor_6_collision'>
        <pose>0 0 0 0 0 0</pose>
        <geometry>
          <cylinder>
            <length>0.005</length>
            <radius>0.1</radius>
          </cylinder>
        </geometry>
        <surface>
          <contact>
            <ode/>
          </contact>
          <friction>
            <ode/>
          </friction>
        </surface>
      </collision>
      <visual name='rotor_6_visual'>
        <pose>0 0 0 0 0 0</pose>
        <geometry>
          <mesh>
            <scale>1.4 1.4 1</scale>
            <uri>model://OrcaXL/meshes/iris_prop_cw.dae</uri>
          </mesh>
        </geometry>
        <material>
          <script>
            <name>Gazebo/DarkGrey</name>
            <uri>__default__</uri>
          </script>
        </material>
      </visual>
      <gravity>1</gravity>
      <velocity_decay/>
      <self_collide>0</self_collide>
    </link>
    <joint name='rotor_6_joint' type='revolute'>
      <child>rotor_6</child>
      <parent>motor_6</parent>
      <axis>
        <xyz>0 0 1</xyz>
        <limit>
          <lower>-1e+16</lower>
          <upper>1e+16</upper>
        </limit>
        <dynamics>
          <spring_reference>0</spring_reference>
          <spring_stiffness>0</spring_stiffness>
        </dynamics>
        <use_parent_model_frame>1</use_parent_model_frame>
      </axis>
    </joint>

    <link name='motor_7'>
      <pose>-0.7 -1.5 0.85 0 0</pose>
      <inertial>
        <pose>0 0 0 0 0 0</pose>
        <mass>0.05</mass>
        <inertia>
          <ixx>0.0166704</ixx>
          <ixy>0</ixy>
          <ixz>0</ixz>
          <iyy>0.0166704</iyy>
          <iyz>0</iyz>
          <izz>0.0167604</izz>
        </inertia>
      </inertial>
      <collision name='motor_7_collision'>
        <pose>0 0 0 0 0 0</pose>
        <geometry>
          <cylinder>
            <length>0.035</length>
            <radius>0.02</radius>
          </cylinder>
        </geometry>
        <surface>
          <contact>
            <ode/>
          </contact>
          <friction>
            <ode/>
          </friction>
        </surface>
      </collision>
      <visual name='motor_7_visual'>
        <pose>0 0 0 0 0 0</pose>
        <geometry>
          <cylinder>
            <length>0.035</length>
            <radius>0.02</radius>
          </cylinder>
        </geometry>
        <material>
          <script>
            <name>Gazebo/DarkGrey</name>
            <uri>__default__</uri>
          </script>
        </material>
      </visual>
      <gravity>1</gravity>
      <velocity_decay/>
      <self_collide>0</self_collide>
    </link>
    <joint name='motor_7_joint' type='fixed'>
      <child>motor_7</child>
      <parent>rear_tilt</parent>
    </joint>

    <link name='rotor_7'>
      <pose>-0.7 -1.5 0.9 0 0 0</pose>
      <inertial>
        <pose>0 0 0 0 0 0</pose>
        <mass>0.005</mass>
        <inertia>
          <ixx>9.75e-07</ixx>
          <ixy>0</ixy>
          <ixz>0</ixz>
          <iyy>0.000166704</iyy>
          <iyz>0</iyz>
          <izz>0.000167604</izz>
        </inertia>
      </inertial>
      <collision name='rotor_7_collision'>
        <pose>0 0 0 0 0 0</pose>
        <geometry>
          <cylinder>
            <length>0.005</length>
            <radius>0.1</radius>
          </cylinder>
        </geometry>
        <surface>
          <contact>
            <ode/>
          </contact>
          <friction>
            <ode/>
          </friction>
        </surface>
      </collision>
      <visual name='rotor_7_visual'>
        <pose>0 0 0 0 0 0</pose>
        <geometry>
          <mesh>
            <scale>1.4 1.4 1</scale>
            <uri>model://OrcaXL/meshes/iris_prop_ccw.dae</uri>
          </mesh>
        </geometry>
        <material>
          <script>
            <name>Gazebo/Blue</name>
            <uri>__default__</uri>
          </script>
        </material>
      </visual>
      <gravity>1</gravity>
      <velocity_decay/>
      <self_collide>0</self_collide>
    </link>
    <joint name='rotor_7_joint' type='revolute'>
      <child>rotor_7</child>
      <parent>motor_7</parent>
      <axis>
        <xyz>0 0 1</xyz>
        <limit>
          <lower>-1e+16</lower>
          <upper>1e+16</upper>
        </limit>
        <dynamics>
          <spring_reference>0</spring_reference>
          <spring_stiffness>0</spring_stiffness>
        </dynamics>
        <use_parent_model_frame>1</use_parent_model_frame>
      </axis>
    </joint>

    <link name="front_left_elevon">
      <pose>1.05 0.65 0.15 0 0 0</pose>
      <inertial>
        <mass>0.00000001</mass>
        <inertia>
          <ixx>0.000001</ixx>
          <ixy>0.0</ixy>
          <iyy>0.000001</iyy>
          <ixz>0.0</ixz>
          <iyz>0.0</iyz>
          <izz>0.000001</izz>
        </inertia>
        <pose>0 0 0 0 0 0</pose>
      </inertial>
      <visual name='front_left_elevon_visual'>
        <pose>0 0.45 0 0 0 1.5707963268</pose>
        <geometry>
          <mesh>
            <scale>0.3 0.5 0.3</scale>
            <uri>model://OrcaXL/meshes/front_wing.dae</uri>
          </mesh>
        </geometry>
        <material>
          <script>
            <name>Gazebo/Blue</name>
            <uri>__default__</uri>
          </script>
        </material>
      </visual>

    </link>
    <joint name='front_left_elevon_joint' type='revolute'>
      <parent>front_left_wing</parent>
      <child>front_left_elevon</child>
      <pose>0 0 0 0 0 0</pose>
      <axis>
        <xyz>0 1 0</xyz>
        <limit>
          <!-- -30/+30 deg. -->
          <lower>-0.53</lower>
          <upper>0.53</upper>
        </limit>
        <dynamics>
          <damping>1.000</damping>
        </dynamics>
      </axis>
      <physics>
        <ode>
          <implicit_spring_damper>1</implicit_spring_damper>
        </ode>
      </physics>
    </joint>

    <link name="rear_left_elevon">
      <pose>-0.7 0.85 0.65 0 0 0</pose>
      <inertial>
        <mass>0.00000001</mass>
        <inertia>
          <ixx>0.000001</ixx>
          <ixy>0.0</ixy>
          <iyy>0.000001</iyy>
          <ixz>0.0</ixz>
          <iyz>0.0</iyz>
          <izz>0.000001</izz>
        </inertia>
        <pose>0 0 0 0 0 0</pose>
      </inertial>
      <visual name='rear_left_elevon_visual'>
        <pose>0.25 0.5 0.5 0 0 1.5707963268</pose>
        <geometry>
          <mesh>
            <scale>0.3 0.5 0.3</scale>
            <uri>model://OrcaXL/meshes/rear_wing.dae</uri>
          </mesh>
        </geometry>
        <material>
          <script>
            <name>Gazebo/Blue</name>
            <uri>__default__</uri>
          </script>
        </material>
      </visual>
    </link>
    <joint name='rear_left_elevon_joint' type='revolute'>
      <parent>rear_left_wing</parent>
      <child>rear_left_elevon</child>
      <pose>0 0 0 0 0 0</pose>
      <axis>
        <xyz>0 1 0</xyz>
        <limit>
          <!-- -30/+30 deg. -->
          <lower>-0.53</lower>
          <upper>0.53</upper>
        </limit>
        <dynamics>
          <damping>1.000</damping>
        </dynamics>
      </axis>
      <physics>
        <ode>
          <implicit_spring_damper>1</implicit_spring_damper>
        </ode>
      </physics>
    </joint>


    <link name="front_right_elevon">
      <pose>1.05 -1.0 0.15 0 0 0</pose>
      <inertial>
        <mass>0.00000001</mass>
        <inertia>
          <ixx>0.000001</ixx>
          <ixy>0.0</ixy>
          <iyy>0.000001</iyy>
          <ixz>0.0</ixz>
          <iyz>0.0</iyz>
          <izz>0.000001</izz>
        </inertia>
        <pose>0 00 0 0.00 0 0.0</pose>
      </inertial>
      <visual name='front_right_elevon_visual'>
        <pose>0 0.4 0 0 0 1.5707963268</pose>
        <geometry>
          <mesh>
            <scale>0.3 0.5 0.3</scale>
            <uri>model://OrcaXL/meshes/front_wing.dae</uri>
          </mesh>
        </geometry>
        <material>
          <script>
            <name>Gazebo/Blue</name>
            <uri>__default__</uri>
          </script>
        </material>
      </visual>

    </link>
    <joint name='front_right_elevon_joint' type='revolute'>
      <parent>front_right_wing</parent>
      <child>front_right_elevon</child>
        <pose>0 00 0 0.00 0 0.0</pose>
      <axis>
        <xyz>0 1 0</xyz>
        <limit>
          <!-- -30/+30 deg. -->
          <lower>-0.53</lower>
          <upper>0.53</upper>
        </limit>
        <dynamics>
          <damping>1.000</damping>
        </dynamics>
      </axis>
      <physics>
        <ode>
          <implicit_spring_damper>1</implicit_spring_damper>
        </ode>
      </physics>
    </joint>
    
    <link name="rear_right_elevon">
      <pose>-0.7 -0.85 0.65 0 0 0</pose>
      <inertial>
        <mass>0.00000001</mass>
        <inertia>
          <ixx>0.000001</ixx>
          <ixy>0.0</ixy>
          <iyy>0.000001</iyy>
          <ixz>0.0</ixz>
          <iyz>0.0</iyz>
          <izz>0.000001</izz>
        </inertia>
        <pose>-0.7 -0.6 0.8 0.00 0 0.0</pose>
      </inertial>
      <visual name='rear_right_elevon_visual'>
        <pose>0.25 0.1 0.5 0 0 1.5707963268</pose>
        <geometry>
          <mesh>
            <scale>0.3 0.5 0.3</scale>
            <uri>model://OrcaXL/meshes/rear_wing.dae</uri>
          </mesh>
        </geometry>
        <material>
          <script>
            <name>Gazebo/Blue</name>
            <uri>__default__</uri>
          </script>
        </material>
      </visual>
    </link>
    <joint name='rear_right_elevon_joint' type='revolute'>
      <parent>rear_right_wing</parent>
      <child>rear_right_elevon</child>
        <pose>0 00 0 0.00 0 0.0</pose>
      <axis>
        <xyz>0 1 0</xyz>
        <limit>
          <!-- -30/+30 deg. -->
          <lower>-0.53</lower>
          <upper>0.53</upper>
        </limit>
        <dynamics>
          <damping>1.000</damping>
        </dynamics>
      </axis>
      <physics>
        <ode>
          <implicit_spring_damper>1</implicit_spring_damper>
        </ode>
      </physics>
    </joint>

    <link name="rudder">
      <inertial>
        <mass>0.00000001</mass>
        <inertia>
          <ixx>0.000001</ixx>
          <ixy>0.0</ixy>
          <iyy>0.000001</iyy>
          <ixz>0.0</ixz>
          <iyz>0.0</iyz>
          <izz>0.000001</izz>
        </inertia>
        <pose>-0.8 0 0.5 0 0 0 </pose>
      </inertial>
    </link>

    <include>
      <uri>model://gps</uri>
      <pose>0 0 0 0 0 0</pose>
      <name>gps</name>
    </include>
    <joint name='gps_joint' type='fixed'>
      <child>gps::link</child>
      <parent>base_link</parent>
    </joint>


    <plugin name="front_left_wing" filename="libLiftDragPlugin.so">
      <a0>0.01984281113</a0>
      <cla>5.4</cla>
      <cda>0.6417112299</cda>
      <cma>0.0</cma>
      <alpha_stall>0.3391428111</alpha_stall>
      <cla_stall>0</cla_stall>
      <cda_stall>-0.9233984055</cda_stall>
      <cma_stall>0</cma_stall>
      <cp>0 0.6 0</cp>
      <area>0.18</area>
      <air_density>1.2041</air_density>
      <forward>1 0 0</forward>
      <upward>0 0 1</upward>
      <link_name>front_tilt</link_name>
      <control_joint_name>
        front_left_elevon_joint
      </control_joint_name>
      <control_joint_rad_to_cl>-2.0</control_joint_rad_to_cl>
      <robotNamespace></robotNamespace>
      <windSubTopic>world_wind</windSubTopic>
    </plugin>

    <plugin name="front_right_wing" filename="libLiftDragPlugin.so">
      <a0>0.01984281113</a0>
      <cla>5.4</cla>
      <cda>0.6417112299</cda>
      <cma>0.0</cma>
      <alpha_stall>0.3391428111</alpha_stall>
      <cla_stall>0</cla_stall>
      <cda_stall>-0.9233984055</cda_stall>
      <cma_stall>0</cma_stall>
      <cp>0 -0.6 0.0</cp>
      <area>0.18</area>
      <air_density>1.2041</air_density>
      <forward>1 0 0</forward>
      <upward>0 0 1</upward>
      <link_name>front_tilt</link_name>
      <control_joint_name>
        front_right_elevon_joint
      </control_joint_name>
      <control_joint_rad_to_cl>-2.0</control_joint_rad_to_cl>
      <robotNamespace></robotNamespace>
      <windSubTopic>world_wind</windSubTopic>
    </plugin>
    <plugin name="rear_left_wing" filename="libLiftDragPlugin.so">
      <a0>0.01984281113</a0>
      <cla>5.4</cla>
      <cda>0.6417112299</cda>
      <cma>0.0</cma>
      <alpha_stall>0.3391428111</alpha_stall>
      <cla_stall>0</cla_stall>
      <cda_stall>-0.9233984055</cda_stall>
      <cma_stall>0</cma_stall>
      <cp>0 0.875 0</cp>
      <area>0.21</area>
      <air_density>1.2041</air_density>
      <forward>1 0 0</forward>
      <upward>0 0 1</upward>
      <link_name>rear_tilt</link_name>
      <control_joint_name>
        rear_left_elevon_joint
      </control_joint_name>
      <control_joint_rad_to_cl>-2.0</control_joint_rad_to_cl>
      <robotNamespace></robotNamespace>
      <windSubTopic>world_wind</windSubTopic>
    </plugin>
    <plugin name="rear_right_wing" filename="libLiftDragPlugin.so">
      <a0>0.01984281113</a0>
      <cla>5.4</cla>
      <cda>0.6417112299</cda>
      <cma>0.0</cma>
      <alpha_stall>0.3391428111</alpha_stall>
      <cla_stall>0</cla_stall>
      <cda_stall>-0.9233984055</cda_stall>
      <cma_stall>0</cma_stall>
      <cp>0 -0.875 0</cp>
      <area>0.21</area>
      <air_density>1.2041</air_density>
      <forward>1 0 0</forward>
      <upward>0 0 1</upward>
      <link_name>rear_tilt</link_name>
      <control_joint_name>
        rear_right_elevon_joint
      </control_joint_name>
      <control_joint_rad_to_cl>-2.0</control_joint_rad_to_cl>
      <robotNamespace></robotNamespace>
      <windSubTopic>world_wind</windSubTopic>
    </plugin>
    <plugin name="rudder" filename="libLiftDragPlugin.so">
      <a0>0.0</a0>
      <cla>4.752798721</cla>
      <cda>1.6417112299</cda>
      <cma>0.0</cma>
      <alpha_stall>0.3391428111</alpha_stall>
      <cla_stall>-3.85</cla_stall>
      <cda_stall>-0.9233984055</cda_stall>
      <cma_stall>0</cma_stall>
      <cp>-0.3 0 0.05</cp>
      <area>0.2</area>
      <air_density>1.2041</air_density>
      <forward>1 0 0</forward>
      <upward>0 1 0</upward>
      <link_name>base_link</link_name>
      <robotNamespace></robotNamespace>
      <windSubTopic>world_wind</windSubTopic>
    </plugin>


    <plugin name='front_left_out_motor_model' filename='libgazebo_motor_model.so'>
      <robotNamespace></robotNamespace>
      <jointName>rotor_0_joint</jointName>
      <linkName>rotor_0</linkName>
      <turningDirection>cw</turningDirection>
      <timeConstantUp>0.0125</timeConstantUp>
      <timeConstantDown>0.025</timeConstantDown>
      <maxRotVelocity>800</maxRotVelocity>
      <motorConstant>1.8e-04</motorConstant>
      <momentConstant>0.27</momentConstant>
      <commandSubTopic>/gazebo/command/motor_speed</commandSubTopic>
      <motorNumber>0</motorNumber>
      <rotorDragCoefficient>0.0000806428</rotorDragCoefficient>
      <rollingMomentCoefficient>1e-06</rollingMomentCoefficient>
      <motorSpeedPubTopic>/motor_speed/0</motorSpeedPubTopic>
      <rotorVelocitySlowdownSim>20</rotorVelocitySlowdownSim>
    </plugin>
    <plugin name='front_left_in_motor_model' filename='libgazebo_motor_model.so'>
      <robotNamespace></robotNamespace>
      <jointName>rotor_1_joint</jointName>
      <linkName>rotor_1</linkName>
      <turningDirection>ccw</turningDirection>
      <timeConstantUp>0.0125</timeConstantUp>
      <timeConstantDown>0.025</timeConstantDown>
      <maxRotVelocity>800</maxRotVelocity>
      <motorConstant>1.8e-04</motorConstant>
      <momentConstant>0.27</momentConstant>
      <commandSubTopic>/gazebo/command/motor_speed</commandSubTopic>
      <motorNumber>1</motorNumber>
      <rotorDragCoefficient>0.0000806428</rotorDragCoefficient>
      <rollingMomentCoefficient>1e-06</rollingMomentCoefficient>
      <motorSpeedPubTopic>/motor_speed/1</motorSpeedPubTopic>
      <rotorVelocitySlowdownSim>20</rotorVelocitySlowdownSim>
    </plugin>
    <plugin name='front_right_in_motor_model' filename='libgazebo_motor_model.so'>
      <robotNamespace></robotNamespace>
      <jointName>rotor_2_joint</jointName>
      <linkName>rotor_2</linkName>
      <turningDirection>cw</turningDirection>
      <timeConstantUp>0.0125</timeConstantUp>
      <timeConstantDown>0.025</timeConstantDown>
      <maxRotVelocity>800</maxRotVelocity>
      <motorConstant>1.8e-04</motorConstant>
      <momentConstant>0.27</momentConstant>
      <commandSubTopic>/gazebo/command/motor_speed</commandSubTopic>
      <motorNumber>2</motorNumber>
      <rotorDragCoefficient>0.0000806428</rotorDragCoefficient>
      <rollingMomentCoefficient>1e-06</rollingMomentCoefficient>
      <motorSpeedPubTopic>/motor_speed/2</motorSpeedPubTopic>
      <rotorVelocitySlowdownSim>20</rotorVelocitySlowdownSim>
    </plugin>
    <plugin name='front_right_out_motor_model' filename='libgazebo_motor_model.so'>
      <robotNamespace></robotNamespace>
      <jointName>rotor_3_joint</jointName>
      <linkName>rotor_3</linkName>
      <turningDirection>ccw</turningDirection>
      <timeConstantUp>0.0125</timeConstantUp>
      <timeConstantDown>0.025</timeConstantDown>
      <maxRotVelocity>800</maxRotVelocity>
      <motorConstant>1.8e-04</motorConstant>
      <momentConstant>0.27</momentConstant>
      <commandSubTopic>/gazebo/command/motor_speed</commandSubTopic>
      <motorNumber>3</motorNumber>
      <rotorDragCoefficient>0.0000806428</rotorDragCoefficient>
      <rollingMomentCoefficient>1e-06</rollingMomentCoefficient>
      <motorSpeedPubTopic>/motor_speed/3</motorSpeedPubTopic>
      <rotorVelocitySlowdownSim>20</rotorVelocitySlowdownSim>
    </plugin>
    <plugin name='back_left_out_motor_model' filename='libgazebo_motor_model.so'>
      <robotNamespace></robotNamespace>
      <jointName>rotor_4_joint</jointName>
      <linkName>rotor_4</linkName>
      <turningDirection>cw</turningDirection>
      <timeConstantUp>0.0125</timeConstantUp>
      <timeConstantDown>0.025</timeConstantDown>
      <maxRotVelocity>800</maxRotVelocity>
      <motorConstant>1.8e-04</motorConstant>
      <momentConstant>0.27</momentConstant>
      <commandSubTopic>/gazebo/command/motor_speed</commandSubTopic>
      <motorNumber>4</motorNumber>
      <rotorDragCoefficient>0.0000806428</rotorDragCoefficient>
      <rollingMomentCoefficient>1e-06</rollingMomentCoefficient>
      <motorSpeedPubTopic>/motor_speed/4</motorSpeedPubTopic>
      <rotorVelocitySlowdownSim>20</rotorVelocitySlowdownSim>
    </plugin>
    <plugin name='back_left_in_motor_model' filename='libgazebo_motor_model.so'>
      <robotNamespace></robotNamespace>
      <jointName>rotor_5_joint</jointName>
      <linkName>rotor_5</linkName>
      <turningDirection>ccw</turningDirection>
      <timeConstantUp>0.0125</timeConstantUp>
      <timeConstantDown>0.025</timeConstantDown>
      <maxRotVelocity>800</maxRotVelocity>
      <motorConstant>1.8e-04</motorConstant>
      <momentConstant>0.27</momentConstant>
      <commandSubTopic>/gazebo/command/motor_speed</commandSubTopic>
      <motorNumber>5</motorNumber>
      <rotorDragCoefficient>0.0000806428</rotorDragCoefficient>
      <rollingMomentCoefficient>1e-06</rollingMomentCoefficient>
      <motorSpeedPubTopic>/motor_speed/5</motorSpeedPubTopic>
      <rotorVelocitySlowdownSim>20</rotorVelocitySlowdownSim>
    </plugin>
    <plugin name='back_right_in_motor_model' filename='libgazebo_motor_model.so'>
      <robotNamespace></robotNamespace>
      <jointName>rotor_6_joint</jointName>
      <linkName>rotor_6</linkName>
      <turningDirection>cw</turningDirection>
      <timeConstantUp>0.0125</timeConstantUp>
      <timeConstantDown>0.025</timeConstantDown>
      <maxRotVelocity>800</maxRotVelocity>
      <motorConstant>1.8e-04</motorConstant>
      <momentConstant>0.27</momentConstant>
      <commandSubTopic>/gazebo/command/motor_speed</commandSubTopic>
      <motorNumber>6</motorNumber>
      <rotorDragCoefficient>0.0000806428</rotorDragCoefficient>
      <rollingMomentCoefficient>1e-06</rollingMomentCoefficient>
      <motorSpeedPubTopic>/motor_speed/6</motorSpeedPubTopic>
      <rotorVelocitySlowdownSim>20</rotorVelocitySlowdownSim>
    </plugin>
    <plugin name='back_right_out_motor_model' filename='libgazebo_motor_model.so'>
      <robotNamespace></robotNamespace>
      <jointName>rotor_7_joint</jointName>
      <linkName>rotor_7</linkName>
      <turningDirection>ccw</turningDirection>
      <timeConstantUp>0.0125</timeConstantUp>
      <timeConstantDown>0.025</timeConstantDown>
      <maxRotVelocity>800</maxRotVelocity>
      <motorConstant>1.8e-04</motorConstant>
      <momentConstant>0.27</momentConstant>
      <commandSubTopic>/gazebo/command/motor_speed</commandSubTopic>
      <motorNumber>7</motorNumber>
      <rotorDragCoefficient>0.0000806428</rotorDragCoefficient>
      <rollingMomentCoefficient>1e-06</rollingMomentCoefficient>
      <motorSpeedPubTopic>/motor_speed/7</motorSpeedPubTopic>
      <rotorVelocitySlowdownSim>20</rotorVelocitySlowdownSim>
    </plugin>
    <plugin name='gazebo_imu_plugin' filename='libgazebo_imu_plugin.so'>
      <robotNamespace></robotNamespace>
      <linkName>OrcaXL/imu_link</linkName>
      <imuTopic>/imu</imuTopic>
      <gyroscopeNoiseDensity>0.0003394</gyroscopeNoiseDensity>
      <gyroscopeRandomWalk>3.8785e-05</gyroscopeRandomWalk>
      <gyroscopeBiasCorrelationTime>1000.0</gyroscopeBiasCorrelationTime>
      <gyroscopeTurnOnBiasSigma>0.0087</gyroscopeTurnOnBiasSigma>
      <accelerometerNoiseDensity>0.004</accelerometerNoiseDensity>
      <accelerometerRandomWalk>0.006</accelerometerRandomWalk>
      <accelerometerBiasCorrelationTime>300.0</accelerometerBiasCorrelationTime>
      <accelerometerTurnOnBiasSigma>0.196</accelerometerTurnOnBiasSigma>
    </plugin>
    <plugin name='groundtruth_plugin' filename='libgazebo_groundtruth_plugin.so'>
      <robotNamespace/>
    </plugin>
    <plugin name='magnetometer_plugin' filename='libgazebo_magnetometer_plugin.so'>
      <robotNamespace/>
      <pubRate>100</pubRate>
      <noiseDensity>0.0004</noiseDensity>
      <randomWalk>6.4e-06</randomWalk>
      <biasCorrelationTime>600</biasCorrelationTime>
      <magTopic>/mag</magTopic>
    </plugin>
    <plugin name='barometer_plugin' filename='libgazebo_barometer_plugin.so'>
      <robotNamespace/>
      <pubRate>50</pubRate>
      <baroTopic>/baro</baroTopic>
    </plugin>
    <plugin name='mavlink_interface' filename='libgazebo_mavlink_interface.so'>
      <robotNamespace></robotNamespace>
      <imuSubTopic>/imu</imuSubTopic>
      <magSubTopic>/mag</magSubTopic>
      <baroSubTopic>/baro</baroSubTopic>
      <mavlink_addr>INADDR_ANY</mavlink_addr>
      <mavlink_tcp_port>4560</mavlink_tcp_port>
      <mavlink_udp_port>14560</mavlink_udp_port>
      <serialEnabled>false</serialEnabled>
      <serialDevice>/dev/ttyACM0</serialDevice>
      <baudRate>921600</baudRate>
      <qgc_addr>INADDR_ANY</qgc_addr>
      <qgc_udp_port>14550</qgc_udp_port>
      <sdk_addr>INADDR_ANY</sdk_addr>
      <sdk_udp_port>14540</sdk_udp_port>
      <hil_mode>false</hil_mode>
      <hil_state_level>false</hil_state_level>
      <enable_lockstep>true</enable_lockstep>
      <use_tcp>true</use_tcp>
      <motorSpeedCommandPubTopic>/gazebo/command/motor_speed</motorSpeedCommandPubTopic>
      <control_channels>
        <channel name="rotor0">
          <input_index>0</input_index>
          <input_offset>0</input_offset>
          <input_scaling>800</input_scaling>
          <zero_position_disarmed>0</zero_position_disarmed>
          <zero_position_armed>0</zero_position_armed>
          <joint_control_type>velocity</joint_control_type>
          <joint_name>rotor_0_joint</joint_name>
        </channel>
        <channel name="rotor1">
          <input_index>1</input_index>
          <input_offset>0</input_offset>
          <input_scaling>800</input_scaling>
          <zero_position_disarmed>0</zero_position_disarmed>
          <zero_position_armed>0</zero_position_armed>
          <joint_control_type>velocity</joint_control_type>
          <joint_name>rotor_1_joint</joint_name>
        </channel>
        <channel name="rotor2">
          <input_index>2</input_index>
          <input_offset>0</input_offset>
          <input_scaling>800</input_scaling>
          <zero_position_disarmed>0</zero_position_disarmed>
          <zero_position_armed>0</zero_position_armed>
          <joint_control_type>velocity</joint_control_type>
          <joint_name>rotor_2_joint</joint_name>
        </channel>
        <channel name="rotor3">
          <input_index>3</input_index>
          <input_offset>0</input_offset>
          <input_scaling>800</input_scaling>
          <zero_position_disarmed>0</zero_position_disarmed>
          <zero_position_armed>0</zero_position_armed>
          <joint_control_type>velocity</joint_control_type>
          <joint_name>rotor_3_joint</joint_name>
        </channel>
        <channel name="rotor4">
          <input_index>4</input_index>
          <input_offset>0</input_offset>
          <input_scaling>800</input_scaling>
          <zero_position_disarmed>0</zero_position_disarmed>
          <zero_position_armed>0</zero_position_armed>
          <joint_control_type>velocity</joint_control_type>
          <joint_name>rotor_4_joint</joint_name>
        </channel>
        <channel name="rotor5">
          <input_index>5</input_index>
          <input_offset>0</input_offset>
          <input_scaling>800</input_scaling>
          <zero_position_disarmed>0</zero_position_disarmed>
          <zero_position_armed>0</zero_position_armed>
          <joint_control_type>velocity</joint_control_type>
          <joint_name>rotor_5_joint</joint_name>
        </channel>
        <channel name="rotor6">
          <input_index>6</input_index>
          <input_offset>0</input_offset>
          <input_scaling>800</input_scaling>
          <zero_position_disarmed>0</zero_position_disarmed>
          <zero_position_armed>0</zero_position_armed>
          <joint_control_type>velocity</joint_control_type>
          <joint_name>rotor_6_joint</joint_name>
        </channel>
        <channel name="rotor7">
          <input_index>7</input_index>
          <input_offset>0</input_offset>
          <input_scaling>800</input_scaling>
          <zero_position_disarmed>0</zero_position_disarmed>
          <zero_position_armed>0</zero_position_armed>
          <joint_control_type>velocity</joint_control_type>
          <joint_name>rotor_7_joint</joint_name>
        </channel>
        <channel name="front_tilt">
          <input_index>8</input_index>
          <input_offset>0.985398</input_offset>
          <input_scaling>0.785398</input_scaling>
          <zero_position_disarmed>0</zero_position_disarmed>
          <zero_position_armed>0</zero_position_armed>
          <joint_control_type>position</joint_control_type>
          <joint_name>front_tilt_joint</joint_name>
           <joint_control_pid>
            <p>10</p>
            <i>0</i>
            <d>0</d>
            <iMax>0.0</iMax>
            <iMin>0.0</iMin>
            <cmdMax>2</cmdMax>
            <cmdMin>-2</cmdMin>
            <errMax>0.2</errMax>
          </joint_control_pid>
        </channel>
        <channel name="rear_tilt">
          <input_index>9</input_index>
          <input_offset>0.985398</input_offset>
          <input_scaling>0.785398</input_scaling>
          <zero_position_disarmed>0</zero_position_disarmed>
          <zero_position_armed>0</zero_position_armed>
          <joint_control_type>position</joint_control_type>
          <joint_name>rear_tilt_joint</joint_name>
           <joint_control_pid>
            <p>10</p>
            <i>0</i>
            <d>0</d>
            <iMax>0.0</iMax>
            <iMin>0.0</iMin>
            <cmdMax>2</cmdMax>
            <cmdMin>-2</cmdMin>
            <errMax>0.2</errMax>
          </joint_control_pid>
        </channel>
        <channel name="front_left_elevon">
          <input_index>10</input_index>
          <input_offset>0</input_offset>
          <input_scaling>1</input_scaling>
          <zero_position_disarmed>0</zero_position_disarmed>
          <zero_position_armed>0</zero_position_armed>
          <joint_control_type>position_kinematic</joint_control_type>
          <joint_name>front_left_elevon_joint</joint_name>
        </channel>
        <channel name="front_right_elevon">
          <input_index>11</input_index>
          <input_offset>0</input_offset>
          <input_scaling>1</input_scaling>
          <zero_position_disarmed>0</zero_position_disarmed>
          <zero_position_armed>0</zero_position_armed>
          <joint_control_type>position_kinematic</joint_control_type>
          <joint_name>right_elevon_joint</joint_name>
        </channel>
        <channel name="rear_left_elevon">
          <input_index>12</input_index>
          <input_offset>0</input_offset>
          <input_scaling>1</input_scaling>
          <zero_position_disarmed>0</zero_position_disarmed>
          <zero_position_armed>0</zero_position_armed>
          <joint_control_type>position_kinematic</joint_control_type>
          <joint_name>rear_left_elevon_joint</joint_name>
        </channel>
        <channel name="rear_right_elevon">
          <input_index>13</input_index>
          <input_offset>0</input_offset>
          <input_scaling>1</input_scaling>
          <zero_position_disarmed>0</zero_position_disarmed>
          <zero_position_armed>0</zero_position_armed>
          <joint_control_type>position_kinematic</joint_control_type>
          <joint_name>rear_left_elevon_joint</joint_name>
        </channel>
      </control_channels>
    </plugin>
    <static>0</static>
  </model>
</sdf>